<?xml version="1.0" ?>
<mujoco model="UR5e">
  <compiler angle="radian" balanceinertia="true"/>
  <option gravity="0 0 0" noslip_iterations="5" noslip_tolerance="1e-8" integrator="implicitfast" impratio="10"> </option>
  <visual>
    <global offwidth="640" offheight="480"/>
    <quality shadowsize="4096"/>
  </visual>
  <default>
    <default class="robot">
      <default class="visual">
        <geom contype="0" conaffinity="0" group="2"/>
      </default>
      <default class="collision">
        <geom contype="1" conaffinity="1" group="3" condim="4"/>
      </default>
    </default>
  </default>
  <asset>
    <mesh name="MESH_base_bd1b2dd6" file="../meshes/base_bd1b2dd6.stl"/>
    <mesh name="MESH_base_b81001a2_0" file="../meshes/base_b81001a2_0.obj"/>
    <mesh name="MESH_base_b81001a2_1" file="../meshes/base_b81001a2_1.obj"/>
    <mesh name="MESH_shoulder_661339ad" file="../meshes/shoulder_661339ad.stl"/>
    <mesh name="MESH_shoulder_0fe2d913_0" file="../meshes/shoulder_0fe2d913_0.obj"/>
    <mesh name="MESH_shoulder_0fe2d913_1" file="../meshes/shoulder_0fe2d913_1.obj"/>
    <mesh name="MESH_shoulder_0fe2d913_2" file="../meshes/shoulder_0fe2d913_2.obj"/>
    <mesh name="MESH_upperarm_d0455716" file="../meshes/upperarm_d0455716.stl"/>
    <mesh name="MESH_upperarm_12b51e98_0" file="../meshes/upperarm_12b51e98_0.obj"/>
    <mesh name="MESH_upperarm_12b51e98_1" file="../meshes/upperarm_12b51e98_1.obj"/>
    <mesh name="MESH_upperarm_12b51e98_2" file="../meshes/upperarm_12b51e98_2.obj"/>
    <mesh name="MESH_upperarm_12b51e98_3" file="../meshes/upperarm_12b51e98_3.obj"/>
    <mesh name="MESH_upperarm_12b51e98_4" file="../meshes/upperarm_12b51e98_4.obj"/>
    <mesh name="MESH_upperarm_12b51e98_5" file="../meshes/upperarm_12b51e98_5.obj"/>
    <mesh name="MESH_upperarm_12b51e98_6" file="../meshes/upperarm_12b51e98_6.obj"/>
    <mesh name="MESH_upperarm_12b51e98_7" file="../meshes/upperarm_12b51e98_7.obj"/>
    <mesh name="MESH_forearm_98bdcf8e" file="../meshes/forearm_98bdcf8e.stl"/>
    <mesh name="MESH_forearm_861ccd15_0" file="../meshes/forearm_861ccd15_0.obj"/>
    <mesh name="MESH_forearm_861ccd15_1" file="../meshes/forearm_861ccd15_1.obj"/>
    <mesh name="MESH_forearm_861ccd15_2" file="../meshes/forearm_861ccd15_2.obj"/>
    <mesh name="MESH_forearm_861ccd15_3" file="../meshes/forearm_861ccd15_3.obj"/>
    <mesh name="MESH_forearm_861ccd15_4" file="../meshes/forearm_861ccd15_4.obj"/>
    <mesh name="MESH_forearm_861ccd15_5" file="../meshes/forearm_861ccd15_5.obj"/>
    <mesh name="MESH_forearm_861ccd15_6" file="../meshes/forearm_861ccd15_6.obj"/>
    <mesh name="MESH_wrist1_2df87b9f" file="../meshes/wrist1_2df87b9f.stl"/>
    <mesh name="MESH_wrist1_1e3ee180_0" file="../meshes/wrist1_1e3ee180_0.obj"/>
    <mesh name="MESH_wrist1_1e3ee180_1" file="../meshes/wrist1_1e3ee180_1.obj"/>
    <mesh name="MESH_wrist1_1e3ee180_2" file="../meshes/wrist1_1e3ee180_2.obj"/>
    <mesh name="MESH_wrist2_e6869549" file="../meshes/wrist2_e6869549.stl"/>
    <mesh name="MESH_wrist2_bde41993_0" file="../meshes/wrist2_bde41993_0.obj"/>
    <mesh name="MESH_wrist2_bde41993_1" file="../meshes/wrist2_bde41993_1.obj"/>
    <mesh name="MESH_wrist2_bde41993_2" file="../meshes/wrist2_bde41993_2.obj"/>
    <mesh name="MESH_wrist3_21abe53b" file="../meshes/wrist3_21abe53b.stl"/>
    <mesh name="MESH_wrist3_8e7adc5c_0" file="../meshes/wrist3_8e7adc5c_0.obj"/>
    <mesh name="MESH_RealSense_D435_Shelf_d359ca29" file="../meshes/RealSense_D435_Shelf_d359ca29.STL"/>
    <mesh name="MESH_ur_to_robotiq_adapter_c1f8affd" file="../meshes/ur_to_robotiq_adapter_c1f8affd.stl"/>
    <mesh name="MESH_ur_to_robotiq_adapter_e07b68cf_0" file="../meshes/ur_to_robotiq_adapter_e07b68cf_0.obj"/>
    <mesh name="MESH_ur_to_robotiq_adapter_e07b68cf_1" file="../meshes/ur_to_robotiq_adapter_e07b68cf_1.obj"/>
    <mesh name="MESH_robotiq_base_e14b1363" file="../meshes/robotiq_base_e14b1363.stl"/>
    <mesh name="MESH_robotiq_base_ba4c22e7_0" file="../meshes/robotiq_base_ba4c22e7_0.obj"/>
    <mesh name="MESH_robotiq_base_ba4c22e7_1" file="../meshes/robotiq_base_ba4c22e7_1.obj"/>
    <mesh name="MESH_left_knuckle_51d3a21e" file="../meshes/left_knuckle_51d3a21e.stl"/>
    <mesh name="MESH_left_knuckle_ac6d7519_0" file="../meshes/left_knuckle_ac6d7519_0.obj"/>
    <mesh name="MESH_left_finger_1b48fede" file="../meshes/left_finger_1b48fede.stl"/>
    <mesh name="MESH_left_finger_e1ea88f9_0" file="../meshes/left_finger_e1ea88f9_0.obj"/>
    <mesh name="MESH_left_finger_e1ea88f9_1" file="../meshes/left_finger_e1ea88f9_1.obj"/>
    <mesh name="MESH_left_finger_tip_c9609174" file="../meshes/left_finger_tip_c9609174.stl"/>
    <mesh name="MESH_left_finger_tip_4c918411_0" file="../meshes/left_finger_tip_4c918411_0.obj"/>
    <mesh name="MESH_left_finger_tip_4c918411_1" file="../meshes/left_finger_tip_4c918411_1.obj"/>
    <mesh name="MESH_right_knuckle_8dc62fad" file="../meshes/right_knuckle_8dc62fad.stl"/>
    <mesh name="MESH_right_knuckle_922d025b_0" file="../meshes/right_knuckle_922d025b_0.obj"/>
    <mesh name="MESH_right_finger_df3e86a5" file="../meshes/right_finger_df3e86a5.stl"/>
    <mesh name="MESH_right_finger_12094dbb_0" file="../meshes/right_finger_12094dbb_0.obj"/>
    <mesh name="MESH_right_finger_12094dbb_1" file="../meshes/right_finger_12094dbb_1.obj"/>
    <mesh name="MESH_right_finger_tip_8abbbc6d" file="../meshes/right_finger_tip_8abbbc6d.stl"/>
    <mesh name="MESH_right_finger_tip_5aafdc4f_0" file="../meshes/right_finger_tip_5aafdc4f_0.obj"/>
    <mesh name="MESH_right_finger_tip_5aafdc4f_1" file="../meshes/right_finger_tip_5aafdc4f_1.obj"/>
    <mesh name="MESH_left_inner_knuckle_11ecd5a1" file="../meshes/left_inner_knuckle_11ecd5a1.stl"/>
    <mesh name="MESH_left_inner_knuckle_d6e20ced_0" file="../meshes/left_inner_knuckle_d6e20ced_0.obj"/>
    <mesh name="MESH_left_inner_knuckle_d6e20ced_1" file="../meshes/left_inner_knuckle_d6e20ced_1.obj"/>
    <mesh name="MESH_right_inner_knuckle_2c3a72a4" file="../meshes/right_inner_knuckle_2c3a72a4.stl"/>
    <mesh name="MESH_right_inner_knuckle_8d05a49d_0" file="../meshes/right_inner_knuckle_8d05a49d_0.obj"/>
    <mesh name="MESH_right_inner_knuckle_8d05a49d_1" file="../meshes/right_inner_knuckle_8d05a49d_1.obj"/>
    <mesh name="MESH_d435_6743a526_0" file="../meshes/d435_6743a526_0.obj"/>
    <mesh name="MESH_d435_6743a526_1" file="../meshes/d435_6743a526_1.obj"/>
    <mesh name="MESH_d435_6743a526_2" file="../meshes/d435_6743a526_2.obj"/>
    <mesh name="MESH_d435_6743a526_3" file="../meshes/d435_6743a526_3.obj"/>
    <mesh name="MESH_d435_6743a526_4" file="../meshes/d435_6743a526_4.obj"/>
    <mesh name="MESH_d435_6743a526_5" file="../meshes/d435_6743a526_5.obj"/>
    <mesh name="MESH_d435_6743a526_6" file="../meshes/d435_6743a526_6.obj"/>
    <mesh name="MESH_d435_6743a526_7" file="../meshes/d435_6743a526_7.obj"/>
    <mesh name="MESH_d435_6743a526_8" file="../meshes/d435_6743a526_8.obj"/>
    <mesh name="MESH_d435_6743a526_9" file="../meshes/d435_6743a526_9.obj"/>
    <mesh name="MESH_d435_6743a526_10" file="../meshes/d435_6743a526_10.obj"/>
    <mesh name="MESH_d435_6743a526_11" file="../meshes/d435_6743a526_11.obj"/>
    <mesh name="MESH_d435_6743a526_12" file="../meshes/d435_6743a526_12.obj"/>
    <mesh name="MESH_d435_6743a526_13" file="../meshes/d435_6743a526_13.obj"/>
    <mesh name="MESH_d435_6743a526_14" file="../meshes/d435_6743a526_14.obj"/>
    <mesh name="MESH_d435_6743a526_15" file="../meshes/d435_6743a526_15.obj"/>
    <mesh name="MESH_d435_6743a526_16" file="../meshes/d435_6743a526_16.obj"/>
    <mesh name="MESH_d435_6743a526_17" file="../meshes/d435_6743a526_17.obj"/>
    <mesh name="MESH_lens_0_95837269" file="../meshes/lens_0_95837269.stl"/>
    <mesh name="MESH_lens_1_0ea760e3" file="../meshes/lens_1_0ea760e3.stl"/>
    <mesh name="MESH_lens_2_17e9b118" file="../meshes/lens_2_17e9b118.stl"/>
    <mesh name="MESH_lens_3_374e2d52" file="../meshes/lens_3_374e2d52.stl"/>
    <mesh name="MESH_lens_4_f4180c93" file="../meshes/lens_4_f4180c93.stl"/>
    <mesh name="MESH_lens_5_7c8fdeea" file="../meshes/lens_5_7c8fdeea.stl"/>
    <mesh name="MESH_lens_6_d1d8923f" file="../meshes/lens_6_d1d8923f.stl"/>
    <mesh name="MESH_lens_7_fc00ca60" file="../meshes/lens_7_fc00ca60.stl"/>
    <mesh name="MESH_lens_8_7af0c489" file="../meshes/lens_8_7af0c489.stl"/>
    <mesh name="MESH_lens_f8a76047" file="../meshes/lens_f8a76047.STL"/>
    <material name="floor" texture="floor" texuniform="true" texrepeat="5 5" reflectance="0.2"/>
    <texture name="floor" type="2d" builtin="checker" mark="edge" rgb1="0.2 0.3 0.4" rgb2="0.1 0.2 0.3" markrgb="0.8 0.8 0.8" width="300" height="300"/>
    <texture name="skybox" type="skybox" builtin="gradient" rgb1=".3 .5 .7" rgb2="0 0 0" width="1024" height="1024"/>
    <!-- <texture name="cube_A_link_TEXTURE" file="../assets/tag36h11-100.png" type="2d"/> -->
    <!-- <material name="cube_A_link_TEXTURE" texture="cube_A_link_TEXTURE"/> -->
    <!-- <texture name="cube_B_link_TEXTURE" file="../assets/tag36h11-101.png" type="2d"/> -->
    <!-- <material name="cube_B_link_TEXTURE" texture="cube_B_link_TEXTURE"/> -->
    <material name="aluminum" rgba="0.5 0.5 0.5 1"/>
    <material name="plastic" rgba="0.1 0.1 0.1 1"/>
  </asset>
  <worldbody>
    <!-- <body name="cube_A_link" pos="0.5 0.135 0.025" quat="1.0 0.0 0.0 0.0">
      <inertial mass="0.5" diaginertia="5e-04 5e-04 5e-04" pos="0 0 0" quat="1.0 0.0 0.0 0.0"/>
      <geom class="collision" name="COLLISION_cube_A_link_0" type="box" pos="0 0 0" quat="1.0 0.0 0.0 0.0" size="0.025 0.025 0.025"/>
      <geom class="visual" name="VISUAL_cube_A_link_0" type="box" pos="0 0 0" quat="1.0 0.0 0.0 0.0" size="0.025 0.025 0.025"/>
      <geom class="visual" name="cube_A_link_TEXTURE" type="box" material="cube_A_link_TEXTURE" pos="0.0 0.0 0.025" euler="0.0 0.0 0.0" size="0.025 0.025 1e-5"/>
      <freejoint/>
    </body>
    <body name="cube_B_link" pos="0.5 0.5 0.025" quat="1.0 0.0 0.0 0.0">
      <inertial mass="0.5" diaginertia="5e-04 5e-04 5e-04" pos="0 0 0" quat="1.0 0.0 0.0 0.0"/>
      <geom class="collision" name="COLLISION_cube_B_link_0" type="box" pos="0 0 0" quat="1.0 0.0 0.0 0.0" size="0.025 0.025 0.025"/>
      <geom class="visual" name="VISUAL_cube_B_link_0" type="box" pos="0 0 0" quat="1.0 0.0 0.0 0.0" size="0.025 0.025 0.025"/>
      <geom class="visual" name="cube_B_link_TEXTURE" type="box" material="cube_B_link_TEXTURE" pos="0.0 0.0 0.025" euler="0.0 0.0 0.0" size="0.025 0.025 1e-5"/>
      <freejoint/>
    </body> -->
    <body name="ur_base_link" pos="0 0 0.5" quat="0.0 0.0 0.0 1.0">
      <body name="ur_base_link_inertia" pos="0 0 0" quat="6.123233995736766e-17 0.0 0.0 1.0">
        <inertial mass="4.0" diaginertia="0.00443333156 0.00443333156 0.0072" pos="0 0 0" quat="1.0 0.0 0.0 0.0"/>
        <geom class="collision" name="COLLISION_ur_base_link_inertia_0" type="mesh" mesh="MESH_base_bd1b2dd6" pos="0 0 0" quat="6.123233995736766e-17 0.0 0.0 1.0"/>
        <geom class="visual" name="VISUAL_ur_base_link_inertia_0" type="mesh" mesh="MESH_base_b81001a2_0" rgba="0.27843137 0.27843137 0.27843137 1.0" pos="0 0 0" quat="6.123233995736766e-17 0.0 0.0 1.0"/>
        <geom class="visual" name="VISUAL_ur_base_link_inertia_1" type="mesh" mesh="MESH_base_b81001a2_1" rgba="0.03137255 0.03137255 0.03137255 1.0" pos="0 0 0" quat="6.123233995736766e-17 0.0 0.0 1.0"/>
        <body name="ur_shoulder_link" pos="0 0 0.1625" quat="1.0 0.0 0.0 0.0">
          <inertial mass="3.761" diaginertia="0.006024775831167757 0.0070003048838239885 0.007030789285008251" pos="0.0 -0.00193 -0.02561" quat="0.20206705998679322 0.6747312134749398 0.365097644892179 -0.6087777940473136"/>
          <joint name="ur_shoulder_pan_joint" type="hinge" axis="0 0 1" ref="" range="-6.283185307179586 6.283185307179586"/>
          <geom class="collision" name="COLLISION_ur_shoulder_link_0" type="mesh" mesh="MESH_shoulder_661339ad" pos="0 0 0" quat="6.123233995736766e-17 0.0 0.0 1.0"/>
          <geom class="visual" name="VISUAL_ur_shoulder_link_0" type="mesh" mesh="MESH_shoulder_0fe2d913_0" rgba="0.27843137 0.27843137 0.27843137 1.0" pos="0 0 0" quat="6.123233995736766e-17 0.0 0.0 1.0"/>
          <geom class="visual" name="VISUAL_ur_shoulder_link_1" type="mesh" mesh="MESH_shoulder_0fe2d913_1" rgba="0.03137255 0.03137255 0.03137255 1.0" pos="0 0 0" quat="6.123233995736766e-17 0.0 0.0 1.0"/>
          <geom class="visual" name="VISUAL_ur_shoulder_link_2" type="mesh" mesh="MESH_shoulder_0fe2d913_2" rgba="0.49019608 0.67843137 0.8 1.0" pos="0 0 0" quat="6.123233995736766e-17 0.0 0.0 1.0"/>
          <body name="ur_upper_arm_link" pos="0 0 0" quat="0.7071067811140325 0.7071067812590626 0.0 0.0">
            <inertial mass="8.058" diaginertia="0.015058840753982044 0.3324720677719464 0.3338808714740716" pos="-0.2125 0.0 0.11336" quat="0.7066521546519151 0.7075611104882223 5.365436380901162e-05 -6.611874721869904e-05"/>
            <joint name="ur_shoulder_lift_joint" type="hinge" axis="0 0 1" ref="" range="-6.283185307179586 6.283185307179586"/>
            <geom class="collision" name="COLLISION_ur_upper_arm_link_0" type="mesh" mesh="MESH_upperarm_d0455716" pos="0 0 0.138" quat="0.5000000000000001 0.5 -0.4999999999999999 -0.5"/>
            <geom class="visual" name="VISUAL_ur_upper_arm_link_0" type="mesh" mesh="MESH_upperarm_12b51e98_0" rgba="0.49019608 0.67843137 0.8 1.0" pos="0 0 0.138" quat="0.5000000000000001 0.5 -0.4999999999999999 -0.5"/>
            <geom class="visual" name="VISUAL_ur_upper_arm_link_1" type="mesh" mesh="MESH_upperarm_12b51e98_1" rgba="0.27843137 0.27843137 0.27843137 1.0" pos="0 0 0.138" quat="0.5000000000000001 0.5 -0.4999999999999999 -0.5"/>
            <geom class="visual" name="VISUAL_ur_upper_arm_link_2" type="mesh" mesh="MESH_upperarm_12b51e98_2" rgba="0.03137255 0.03137255 0.03137255 1.0" pos="0 0 0.138" quat="0.5000000000000001 0.5 -0.4999999999999999 -0.5"/>
            <geom class="visual" name="VISUAL_ur_upper_arm_link_3" type="mesh" mesh="MESH_upperarm_12b51e98_3" rgba="0.49019608 0.67843137 0.8 1.0" pos="0 0 0.138" quat="0.5000000000000001 0.5 -0.4999999999999999 -0.5"/>
            <geom class="visual" name="VISUAL_ur_upper_arm_link_4" type="mesh" mesh="MESH_upperarm_12b51e98_4" rgba="0.81960784 0.81960784 0.81960784 1.0" pos="0 0 0.138" quat="0.5000000000000001 0.5 -0.4999999999999999 -0.5"/>
            <geom class="visual" name="VISUAL_ur_upper_arm_link_5" type="mesh" mesh="MESH_upperarm_12b51e98_5" rgba="0.03137255 0.03137255 0.03137255 1.0" pos="0 0 0.138" quat="0.5000000000000001 0.5 -0.4999999999999999 -0.5"/>
            <geom class="visual" name="VISUAL_ur_upper_arm_link_6" type="mesh" mesh="MESH_upperarm_12b51e98_6" rgba="0.27843137 0.27843137 0.27843137 1.0" pos="0 0 0.138" quat="0.5000000000000001 0.5 -0.4999999999999999 -0.5"/>
            <geom class="visual" name="VISUAL_ur_upper_arm_link_7" type="mesh" mesh="MESH_upperarm_12b51e98_7" rgba="0.03137255 0.03137255 0.03137255 1.0" pos="0 0 0.138" quat="0.5000000000000001 0.5 -0.4999999999999999 -0.5"/>
            <body name="ur_forearm_link" pos="-0.425 0 0" quat="1.0 0.0 0.0 0.0">
              <inertial mass="2.846" diaginertia="0.003971028904819707 0.0785102224320644 0.07879270866311583" pos="-0.2422 0.0 0.0265" quat="0.6984488939206283 0.715600664432383 -0.006368275363090868 -0.006654074983260038"/>
              <joint name="ur_elbow_joint" type="hinge" axis="0 0 1" ref="" range="-3.141592653589793 3.141592653589793"/>
              <geom class="collision" name="COLLISION_ur_forearm_link_0" type="mesh" mesh="MESH_forearm_98bdcf8e" pos="0 0 0.007" quat="0.5000000000000001 0.5 -0.4999999999999999 -0.5"/>
              <geom class="visual" name="VISUAL_ur_forearm_link_0" type="mesh" mesh="MESH_forearm_861ccd15_0" rgba="0.27843137 0.27843137 0.27843137 1.0" pos="0 0 0.007" quat="0.5000000000000001 0.5 -0.4999999999999999 -0.5"/>
              <geom class="visual" name="VISUAL_ur_forearm_link_1" type="mesh" mesh="MESH_forearm_861ccd15_1" rgba="0.27843137 0.27843137 0.27843137 1.0" pos="0 0 0.007" quat="0.5000000000000001 0.5 -0.4999999999999999 -0.5"/>
              <geom class="visual" name="VISUAL_ur_forearm_link_2" type="mesh" mesh="MESH_forearm_861ccd15_2" rgba="0.03137255 0.03137255 0.03137255 1.0" pos="0 0 0.007" quat="0.5000000000000001 0.5 -0.4999999999999999 -0.5"/>
              <geom class="visual" name="VISUAL_ur_forearm_link_3" type="mesh" mesh="MESH_forearm_861ccd15_3" rgba="0.81960784 0.81960784 0.81960784 1.0" pos="0 0 0.007" quat="0.5000000000000001 0.5 -0.4999999999999999 -0.5"/>
              <geom class="visual" name="VISUAL_ur_forearm_link_4" type="mesh" mesh="MESH_forearm_861ccd15_4" rgba="0.03137255 0.03137255 0.03137255 1.0" pos="0 0 0.007" quat="0.5000000000000001 0.5 -0.4999999999999999 -0.5"/>
              <geom class="visual" name="VISUAL_ur_forearm_link_5" type="mesh" mesh="MESH_forearm_861ccd15_5" rgba="0.49019608 0.67843137 0.8 1.0" pos="0 0 0.007" quat="0.5000000000000001 0.5 -0.4999999999999999 -0.5"/>
              <geom class="visual" name="VISUAL_ur_forearm_link_6" type="mesh" mesh="MESH_forearm_861ccd15_6" rgba="0.03137255 0.03137255 0.03137255 1.0" pos="0 0 0.007" quat="0.5000000000000001 0.5 -0.4999999999999999 -0.5"/>
              <body name="ur_wrist_1_link" pos="-0.3922 0 0.1333" quat="1.0 0.0 0.0 0.0">
                <inertial mass="1.37" diaginertia="0.0011986756140664695 0.0014236273687040747 0.0016550170172294559" pos="0.0 -0.01634 -0.0018" quat="0.617164970477703 0.3485939338997156 0.334307835150133 0.6211504969174605"/>
                <joint name="ur_wrist_1_joint" type="hinge" axis="0 0 1" ref="" range="-6.283185307179586 6.283185307179586"/>
                <geom class="collision" name="COLLISION_ur_wrist_1_link_0" type="mesh" mesh="MESH_wrist1_2df87b9f" pos="0 0 -0.127" quat="0.7071067811865476 0.7071067811865475 0.0 0.0"/>
                <geom class="visual" name="VISUAL_ur_wrist_1_link_0" type="mesh" mesh="MESH_wrist1_1e3ee180_0" rgba="0.27843137 0.27843137 0.27843137 1.0" pos="0 0 -0.127" quat="0.7071067811865476 0.7071067811865475 0.0 0.0"/>
                <geom class="visual" name="VISUAL_ur_wrist_1_link_1" type="mesh" mesh="MESH_wrist1_1e3ee180_1" rgba="0.49019608 0.67843137 0.8 1.0" pos="0 0 -0.127" quat="0.7071067811865476 0.7071067811865475 0.0 0.0"/>
                <geom class="visual" name="VISUAL_ur_wrist_1_link_2" type="mesh" mesh="MESH_wrist1_1e3ee180_2" rgba="0.03137255 0.03137255 0.03137255 1.0" pos="0 0 -0.127" quat="0.7071067811865476 0.7071067811865475 0.0 0.0"/>
                <body name="ur_wrist_2_link" pos="0 -0.0997 -2.044881182297852e-11" quat="0.7071067811140325 0.7071067812590626 0.0 0.0">
                  <inertial mass="1.3" diaginertia="0.0009581396620642861 0.001286066344108885 0.001356373993826829" pos="0.0 0.01634 -0.0018" quat="0.5288470911292525 -0.47465159334892915 -0.4440672234695894 0.5457388754481953"/>
                  <joint name="ur_wrist_2_joint" type="hinge" axis="0 0 1" ref="" range="-6.283185307179586 6.283185307179586"/>
                  <geom class="collision" name="COLLISION_ur_wrist_2_link_0" type="mesh" mesh="MESH_wrist2_e6869549" pos="0 0 -0.0997" quat="1.0 0.0 0.0 0.0"/>
                  <geom class="visual" name="VISUAL_ur_wrist_2_link_0" type="mesh" mesh="MESH_wrist2_bde41993_0" rgba="0.27843137 0.27843137 0.27843137 1.0" pos="0 0 -0.0997" quat="1.0 0.0 0.0 0.0"/>
                  <geom class="visual" name="VISUAL_ur_wrist_2_link_1" type="mesh" mesh="MESH_wrist2_bde41993_1" rgba="0.49019608 0.67843137 0.8 1.0" pos="0 0 -0.0997" quat="1.0 0.0 0.0 0.0"/>
                  <geom class="visual" name="VISUAL_ur_wrist_2_link_2" type="mesh" mesh="MESH_wrist2_bde41993_2" rgba="0.03137255 0.03137255 0.03137255 1.0" pos="0 0 -0.0997" quat="1.0 0.0 0.0 0.0"/>
                  <body name="ur_wrist_3_link" pos="0 0.0996 -2.042830148012698e-11" quat="0.7071067811140325 -0.7071067812590626 8.659560562354933e-17 8.880527684815676e-27">
                    <inertial mass="0.365" diaginertia="0.00018693802309626027 0.00018906920634770998 0.0002575727705560295" pos="0.0 0.0 -0.001159" quat="0.9998848543715624 -0.006732397405301183 0.0011178804501228406 0.013553714134353398"/>
                    <joint name="ur_wrist_3_joint" type="hinge" axis="0 0 1" ref="" range="-6.283185307179586 6.283185307179586"/>
                    <geom class="collision" name="COLLISION_ur_wrist_3_link_0" type="mesh" mesh="MESH_wrist3_21abe53b" pos="0 0 -0.0989" quat="0.7071067811865476 0.7071067811865475 0.0 0.0"/>
                    <geom class="visual" name="VISUAL_ur_wrist_3_link_0" type="mesh" mesh="MESH_wrist3_8e7adc5c_0" rgba="0.81960784 0.81960784 0.81960784 1.0" pos="0 0 -0.0989" quat="0.7071067811865476 0.7071067811865475 0.0 0.0"/>
                    <!-- <body name="ur_ft_frame" pos="0 0 0" quat="6.123233995736766e-17 1.0 0.0 0.0"> -->
                      <!-- <site name="ur_ft_frame_SITE" pos="0 0 0" quat="1 0 0 0"/> -->
                    <!-- </body> -->
                    <body name="ur_flange" pos="0 0 0" quat="0.5000000000000001 -0.4999999999999999 -0.5 -0.5">
                      <body name="ur_tool0" pos="0 0 0" quat="0.5000000000000001 0.5 0.4999999999999999 0.5">
                      <site name="ur_ft_frame_SITE" pos="0 0 0" quat="1 0 0 0"/>
                        <body name="realsense_shelf" pos="0.0 0.0 0.0" quat="6.123233995736766e-17 0.0 0.0 1.0">
                          <inertial mass="0.038" diaginertia="6.673e-05 8.5e-06 7.517e-05" pos="0.0 0.044 0.0015" quat="1.0 0.0 0.0 0.0"/>
                          <geom class="collision" name="COLLISION_realsense_shelf_0" type="mesh" mesh="MESH_RealSense_D435_Shelf_d359ca29" pos="0 0 0" quat="1.0 0.0 0.0 0.0"/>
                          <geom class="visual" name="VISUAL_realsense_shelf_0" type="mesh" mesh="MESH_RealSense_D435_Shelf_d359ca29" rgba="0.7 0.7 0.7 1.0" pos="0 0 0" quat="1.0 0.0 0.0 0.0"/>
                          <body name="realsense_shelf_child_side" pos="0.0 0.0 0.006" quat="1.0 0.0 0.0 0.0">
                            <body name="robotiq_ur_to_robotiq_link" pos="0 0 0" quat="1.0 0.0 0.0 0.0">
                              <inertial mass="0.01" diaginertia="4.4e-05 2.7e-05 2.7e-05" pos="0 0 0" quat="1.0 0.0 0.0 0.0"/>
                              <geom class="collision" name="COLLISION_robotiq_ur_to_robotiq_link_0" type="mesh" mesh="MESH_ur_to_robotiq_adapter_c1f8affd" pos="0 0 0" quat="1.0 0.0 0.0 0.0"/>
                              <geom class="visual" name="VISUAL_robotiq_ur_to_robotiq_link_0" type="mesh" mesh="MESH_ur_to_robotiq_adapter_e07b68cf_0" rgba="0.03921569 0.03921569 0.03921569 1.0" pos="0 0 0" quat="1.0 0.0 0.0 0.0"/>
                              <geom class="visual" name="VISUAL_robotiq_ur_to_robotiq_link_1" type="mesh" mesh="MESH_ur_to_robotiq_adapter_e07b68cf_1" rgba="0.29803922 0.29803922 0.29803922 1.0" pos="0 0 0" quat="1.0 0.0 0.0 0.0"/>
                              <body name="robotiq_ur_to_g2f85_child_side" pos="0 0 0.011" quat="1.0 0.0 0.0 0.0">
                                <body name="robotiq_85_base_link" pos="0 0 0" quat="1.0 0.0 0.0 0.0">
                                  <inertial mass="0.66320197" diaginertia="0.00039462722067250294 0.0005161781480017798 0.0005880226313257172" pos="0.0 2.274e-05 0.03232288" quat="0.5005192813628906 -0.49947997687615325 0.49968467889977636 -0.5003153239274212"/>
                                  <geom class="collision" name="COLLISION_robotiq_85_base_link_0" type="mesh" mesh="MESH_robotiq_base_e14b1363" pos="0 0 0" quat="1.0 0.0 0.0 0.0"/>
                                  <geom class="visual" name="VISUAL_robotiq_85_base_link_0" type="mesh" mesh="MESH_robotiq_base_ba4c22e7_0" rgba="0.03137255 0.03137255 0.03137255 1.0" pos="0 0 0" quat="1.0 0.0 0.0 0.0"/>
                                  <geom class="visual" name="VISUAL_robotiq_85_base_link_1" type="mesh" mesh="MESH_robotiq_base_ba4c22e7_1" rgba="0.8 0.8 0.8 1.0" pos="0 0 0" quat="1.0 0.0 0.0 0.0"/>
                                  <body name="robotiq_85_left_knuckle_link" pos="0.03060114 0.0 0.05490452" quat="1.0 0.0 0.0 0.0">
                                    <inertial mass="0.01384773208" diaginertia="3.4500845003981836e-07 2.238671549960182e-06 2.3194400000000004e-06" pos="0.01213197 0.0002 -0.00058647" quat="0.7067650957173783 -0.706765095717382 -0.02197952400764002 0.021979524007640125"/>
                                    <joint name="robotiq_85_left_knuckle_joint" type="hinge" axis="0 -1 0" ref="" range="0.0 0.8"/>
                                    <geom class="collision" name="COLLISION_robotiq_85_left_knuckle_link_0" type="mesh" mesh="MESH_left_knuckle_51d3a21e" pos="0 0 0" quat="1.0 0.0 0.0 0.0"/>
                                    <geom class="visual" name="VISUAL_robotiq_85_left_knuckle_link_0" type="mesh" mesh="MESH_left_knuckle_ac6d7519_0" rgba="0.8 0.8 0.8 1.0" pos="0 0 0" quat="1.0 0.0 0.0 0.0"/>
                                    <body name="robotiq_85_left_finger_link" pos="0.03152616 0.0 -0.00376347" quat="1.0 0.0 0.0 0.0">
                                      <inertial mass="0.04260376752" diaginertia="4.6822750126340444e-06 1.1832080000000002e-05 1.4372364987365957e-05" pos="0.00346899 -0.00079447 0.01867121" quat="0.620317559743575 1.5660448931166561e-16 -0.7843507666049523 7.817375081343765e-18"/>
                                      <geom class="collision" name="COLLISION_robotiq_85_left_finger_link_0" type="mesh" mesh="MESH_left_finger_1b48fede" pos="0 0 0" quat="1.0 0.0 0.0 0.0"/>
                                      <geom class="visual" name="VISUAL_robotiq_85_left_finger_link_0" type="mesh" mesh="MESH_left_finger_e1ea88f9_0" rgba="0.8 0.8 0.8 1.0" pos="0 0 0" quat="1.0 0.0 0.0 0.0"/>
                                      <geom class="visual" name="VISUAL_robotiq_85_left_finger_link_1" type="mesh" mesh="MESH_left_finger_e1ea88f9_1" rgba="0.03137255 0.03137255 0.03137255 1.0" pos="0 0 0" quat="1.0 0.0 0.0 0.0"/>
                                      <body name="robotiq_85_left_finger_tip_link" pos="0.00563134 0.0 0.04718515" quat="1.0 0.0 0.0 0.0">
                                        <inertial mass="0.04268588744" diaginertia="2.6440466428387786e-06 1.197888e-05 1.206531335716122e-05" pos="-0.01456706 -0.0008 0.01649701" quat="0.0 0.5431343521286145 0.0 0.8396458036206875"/>
                                        <joint name="robotiq_85_left_finger_tip_joint" type="hinge" axis="0 -1 0" ref=""/>
                                        <geom class="collision" name="COLLISION_robotiq_85_left_finger_tip_link_0" type="mesh" mesh="MESH_left_finger_tip_c9609174" pos="0 0 0" quat="1.0 0.0 0.0 0.0"/>
                                        <geom class="visual" name="VISUAL_robotiq_85_left_finger_tip_link_0" type="mesh" mesh="MESH_left_finger_tip_4c918411_0" rgba="0.03137255 0.03137255 0.03137255 1.0" pos="0 0 0" quat="1.0 0.0 0.0 0.0"/>
                                        <geom class="visual" name="VISUAL_robotiq_85_left_finger_tip_link_1" type="mesh" mesh="MESH_left_finger_tip_4c918411_1" rgba="0.8 0.8 0.8 1.0" pos="0 0 0" quat="1.0 0.0 0.0 0.0"/>
                                      </body>
                                    </body>
                                  </body>
                                  <body name="robotiq_85_right_knuckle_link" pos="-0.03060114 0.0 0.05490452" quat="1.0 0.0 0.0 0.0">
                                    <inertial mass="0.01384773208" diaginertia="3.4500845003981836e-07 2.238671549960182e-06 2.3194400000000004e-06" pos="-0.01213197 0.0002 -0.00058647" quat="0.7067650957173783 0.706765095717382 0.02197952400764002 0.021979524007640125"/>
                                    <joint name="robotiq_85_right_knuckle_joint" type="hinge" axis="0 -1 0" ref="" range="-0.8 0.0"/>
                                    <geom class="collision" name="COLLISION_robotiq_85_right_knuckle_link_0" type="mesh" mesh="MESH_right_knuckle_8dc62fad" pos="0 0 0" quat="1.0 0.0 0.0 0.0"/>
                                    <geom class="visual" name="VISUAL_robotiq_85_right_knuckle_link_0" type="mesh" mesh="MESH_right_knuckle_922d025b_0" rgba="0.8 0.8 0.8 1.0" pos="0 0 0" quat="1.0 0.0 0.0 0.0"/>
                                    <body name="robotiq_85_right_finger_link" pos="-0.03152616 0.0 -0.00376347" quat="1.0 0.0 0.0 0.0">
                                      <inertial mass="0.04260376752" diaginertia="4.6822750126340444e-06 1.1832080000000002e-05 1.4372364987365957e-05" pos="-0.00346899 -5.53e-06 0.01867121" quat="1.3536424256716714e-16 0.620317559743575 -1.7693343843959256e-17 0.7843507666049523"/>
                                      <geom class="collision" name="COLLISION_robotiq_85_right_finger_link_0" type="mesh" mesh="MESH_right_finger_df3e86a5" pos="0 0 0" quat="1.0 0.0 0.0 0.0"/>
                                      <geom class="visual" name="VISUAL_robotiq_85_right_finger_link_0" type="mesh" mesh="MESH_right_finger_12094dbb_0" rgba="0.8 0.8 0.8 1.0" pos="0 0 0" quat="1.0 0.0 0.0 0.0"/>
                                      <geom class="visual" name="VISUAL_robotiq_85_right_finger_link_1" type="mesh" mesh="MESH_right_finger_12094dbb_1" rgba="0.03137255 0.03137255 0.03137255 1.0" pos="0 0 0" quat="1.0 0.0 0.0 0.0"/>
                                      <body name="robotiq_85_right_finger_tip_link" pos="-0.00563134 0.0 0.04718515" quat="1.0 0.0 0.0 0.0">
                                        <inertial mass="0.04268588744" diaginertia="2.6440466428387786e-06 1.197888e-05 1.206531335716122e-05" pos="0.01456706 5e-05 0.01649701" quat="0.5431343521286145 0.0 -0.8396458036206876 0.0"/>
                                        <joint name="robotiq_85_right_finger_tip_joint" type="hinge" axis="0 -1 0" ref=""/>
                                        <geom class="collision" name="COLLISION_robotiq_85_right_finger_tip_link_0" type="mesh" mesh="MESH_right_finger_tip_8abbbc6d" pos="0 0 0" quat="1.0 0.0 0.0 0.0"/>
                                        <geom class="visual" name="VISUAL_robotiq_85_right_finger_tip_link_0" type="mesh" mesh="MESH_right_finger_tip_5aafdc4f_0" rgba="0.03137255 0.03137255 0.03137255 1.0" pos="0 0 0" quat="1.0 0.0 0.0 0.0"/>
                                        <geom class="visual" name="VISUAL_robotiq_85_right_finger_tip_link_1" type="mesh" mesh="MESH_right_finger_tip_5aafdc4f_1" rgba="0.8 0.8 0.8 1.0" pos="0 0 0" quat="1.0 0.0 0.0 0.0"/>
                                      </body>
                                    </body>
                                  </body>
                                  <body name="robotiq_85_left_inner_knuckle_link" pos="0.0127 0.0 0.06142" quat="1.0 0.0 0.0 0.0">
                                    <inertial mass="0.02969376448" diaginertia="4.887117939453948e-06 8.690559999999998e-06 1.287568206054605e-05" pos="0.01897699 0.00015001 0.02247101" quat="0.42240861350400083 -2.0734925751478815e-16 -0.9064055180975167 3.062158720512423e-17"/>
                                    <joint name="robotiq_85_left_inner_knuckle_joint" type="hinge" axis="0 -1 0" ref=""/>
                                    <geom class="collision" name="COLLISION_robotiq_85_left_inner_knuckle_link_0" type="mesh" mesh="MESH_left_inner_knuckle_11ecd5a1" pos="0 0 0" quat="1.0 0.0 0.0 0.0"/>
                                    <geom class="visual" name="VISUAL_robotiq_85_left_inner_knuckle_link_0" type="mesh" mesh="MESH_left_inner_knuckle_d6e20ced_0" rgba="0.03137255 0.03137255 0.03137255 1.0" pos="0 0 0" quat="1.0 0.0 0.0 0.0"/>
                                    <geom class="visual" name="VISUAL_robotiq_85_left_inner_knuckle_link_1" type="mesh" mesh="MESH_left_inner_knuckle_d6e20ced_1" rgba="0.8 0.8 0.8 1.0" pos="0 0 0" quat="1.0 0.0 0.0 0.0"/>
                                  </body>
                                  <body name="robotiq_85_right_inner_knuckle_link" pos="-0.0127 0.0 0.06142" quat="1.0 0.0 0.0 0.0">
                                    <inertial mass="0.02969376448" diaginertia="4.880756583548092e-06 8.690560000000002e-06 1.288204341645191e-05" pos="-0.01926824 5.001e-05 0.02222178" quat="2.0694740322688522e-16 0.41391107378742875 6.098000116538267e-17 0.9103173199473564"/>
                                    <joint name="robotiq_85_right_inner_knuckle_joint" type="hinge" axis="0 -1 0" ref=""/>
                                    <geom class="collision" name="COLLISION_robotiq_85_right_inner_knuckle_link_0" type="mesh" mesh="MESH_right_inner_knuckle_2c3a72a4" pos="0 0 0" quat="1.0 0.0 0.0 0.0"/>
                                    <geom class="visual" name="VISUAL_robotiq_85_right_inner_knuckle_link_0" type="mesh" mesh="MESH_right_inner_knuckle_8d05a49d_0" rgba="0.03137255 0.03137255 0.03137255 1.0" pos="0 0 0" quat="1.0 0.0 0.0 0.0"/>
                                    <geom class="visual" name="VISUAL_robotiq_85_right_inner_knuckle_link_1" type="mesh" mesh="MESH_right_inner_knuckle_8d05a49d_1" rgba="0.8 0.8 0.8 1.0" pos="0 0 0" quat="1.0 0.0 0.0 0.0"/>
                                  </body>
                                  <body name="_tcp" pos="0 0 0.12" quat="1.0 0.0 0.0 0.0">
                                    <site name="_tcp" pos="0 0 0" quat="1 0 0 0"/>
                                    <body name="lens_link" pos="0.0 0.0 0.0" quat="1.0 0.0 0.0 0.0">
                                      <inertial mass="0.0438" diaginertia="0.0003246 0.0006287 0.0003223" pos="0 0 0.205" quat="1.0 0.0 0.0 0.0"/>
                                      <geom class="collision" name="COLLISION_lens_link_0" type="mesh" mesh="MESH_lens_0_95837269" pos="0 0 0" quat="1.0 0.0 0.0 0.0"
                                        condim="3" friction="0.05 0.001 0.0001" solref="0.003 1" solimp="0.98 0.995 0.0005 0.5 2" margin="0"/>
                                      <geom class="collision" name="COLLISION_lens_link_1" type="mesh" mesh="MESH_lens_1_0ea760e3" pos="0 0 0" quat="1.0 0.0 0.0 0.0"
                                        condim="3" friction="0.05 0.001 0.0001" solref="0.003 1" solimp="0.98 0.995 0.0005 0.5 2" margin="0"/>
                                      <geom class="collision" name="COLLISION_lens_link_2" type="mesh" mesh="MESH_lens_2_17e9b118" pos="0 0 0" quat="1.0 0.0 0.0 0.0"
                                        condim="3" friction="0.05 0.001 0.0001" solref="0.003 1" solimp="0.98 0.995 0.0005 0.5 2" margin="0"/>
                                      <geom class="collision" name="COLLISION_lens_link_3" type="mesh" mesh="MESH_lens_3_374e2d52" pos="0 0 0" quat="1.0 0.0 0.0 0.0"
                                        condim="3" friction="0.05 0.001 0.0001" solref="0.003 1" solimp="0.98 0.995 0.0005 0.5 2" margin="0"/>
                                      <geom class="collision" name="COLLISION_lens_link_4" type="mesh" mesh="MESH_lens_4_f4180c93" pos="0 0 0" quat="1.0 0.0 0.0 0.0"
                                        condim="3" friction="0.05 0.001 0.0001" solref="0.003 1" solimp="0.98 0.995 0.0005 0.5 2" margin="0"/>
                                      <geom class="collision" name="COLLISION_lens_link_5" type="mesh" mesh="MESH_lens_5_7c8fdeea" pos="0 0 0" quat="1.0 0.0 0.0 0.0"
                                        condim="3" friction="0.05 0.001 0.0001" solref="0.003 1" solimp="0.98 0.995 0.0005 0.5 2" margin="0"/>
                                      <geom class="collision" name="COLLISION_lens_link_6" type="mesh" mesh="MESH_lens_6_d1d8923f" pos="0 0 0" quat="1.0 0.0 0.0 0.0"
                                        condim="3" friction="0.05 0.001 0.0001" solref="0.003 1" solimp="0.98 0.995 0.0005 0.5 2" margin="0"/>
                                      <geom class="collision" name="COLLISION_lens_link_7" type="mesh" mesh="MESH_lens_7_fc00ca60" pos="0 0 0" quat="1.0 0.0 0.0 0.0"
                                        condim="3" friction="0.05 0.001 0.0001" solref="0.003 1" solimp="0.98 0.995 0.0005 0.5 2" margin="0"/>
                                      <geom class="collision" name="COLLISION_lens_link_8" type="mesh" mesh="MESH_lens_8_7af0c489" pos="0 0 0" quat="1.0 0.0 0.0 0.0"
                                        condim="3" friction="0.05 0.001 0.0001" solref="0.003 1" solimp="0.98 0.995 0.0005 0.5 2" margin="0"/>
                                      <geom class="visual" name="VISUAL_lens_link_0" type="mesh" mesh="MESH_lens_f8a76047" rgba="0.7 0.7 0.7 1.0" pos="0 0 0" quat="1.0 0.0 0.0 0.0"/>
                                      <site name="_hole" pos="0 0 0.35" quat="1 0 0 0"/>
                                    </body>
                                  </body>
                                </body>
                              </body>
                            </body>
                          </body>
                          <body name="realsense_bottom_screw_frame" pos="0 0.0875 0.013" quat="0.5000000000000001 -0.4999999999999999 -0.5 -0.5">
                            <body name="realsense_link" pos="0.010600000000000002 0.0175 0.0125" quat="1.0 0.0 0.0 0.0">
                              <inertial mass="0.072" diaginertia="0.003881243 0.00049894 0.003879257" pos="0 0 0" quat="1.0 0.0 0.0 0.0"/>
                              <geom class="collision" name="COLLISION_realsense_link_0" type="box" pos="0 -0.0175 0" quat="1.0 0.0 0.0 0.0" size="0.012525 0.045 0.0125"/>
                              <geom class="visual" name="VISUAL_realsense_link_0" type="mesh" mesh="MESH_d435_6743a526_0" rgba="0.74901961 0.74901961 0.74901961 1.0" pos="0.0043 -0.0175 0" quat="0.5000000000000001 0.5 0.4999999999999999 0.5"/>
                              <geom class="visual" name="VISUAL_realsense_link_1" type="mesh" mesh="MESH_d435_6743a526_1" rgba="0.74901961 0.74901961 0.74901961 1.0" pos="0.0043 -0.0175 0" quat="0.5000000000000001 0.5 0.4999999999999999 0.5"/>
                              <geom class="visual" name="VISUAL_realsense_link_2" type="mesh" mesh="MESH_d435_6743a526_2" rgba="0.74901961 0.74901961 0.74901961 1.0" pos="0.0043 -0.0175 0" quat="0.5000000000000001 0.5 0.4999999999999999 0.5"/>
                              <geom class="visual" name="VISUAL_realsense_link_3" type="mesh" mesh="MESH_d435_6743a526_3" rgba="0.74901961 0.74901961 0.74901961 1.0" pos="0.0043 -0.0175 0" quat="0.5000000000000001 0.5 0.4999999999999999 0.5"/>
                              <geom class="visual" name="VISUAL_realsense_link_4" type="mesh" mesh="MESH_d435_6743a526_4" rgba="0.74901961 0.74901961 0.74901961 1.0" pos="0.0043 -0.0175 0" quat="0.5000000000000001 0.5 0.4999999999999999 0.5"/>
                              <geom class="visual" name="VISUAL_realsense_link_5" type="mesh" mesh="MESH_d435_6743a526_5" rgba="0.74901961 0.74901961 0.74901961 1.0" pos="0.0043 -0.0175 0" quat="0.5000000000000001 0.5 0.4999999999999999 0.5"/>
                              <geom class="visual" name="VISUAL_realsense_link_6" type="mesh" mesh="MESH_d435_6743a526_6" rgba="0.74901961 0.74901961 0.74901961 1.0" pos="0.0043 -0.0175 0" quat="0.5000000000000001 0.5 0.4999999999999999 0.5"/>
                              <geom class="visual" name="VISUAL_realsense_link_7" type="mesh" mesh="MESH_d435_6743a526_7" rgba="0.74901961 0.74901961 0.74901961 1.0" pos="0.0043 -0.0175 0" quat="0.5000000000000001 0.5 0.4999999999999999 0.5"/>
                              <geom class="visual" name="VISUAL_realsense_link_8" type="mesh" mesh="MESH_d435_6743a526_8" rgba="0.74901961 0.74901961 0.74901961 1.0" pos="0.0043 -0.0175 0" quat="0.5000000000000001 0.5 0.4999999999999999 0.5"/>
                              <geom class="visual" name="VISUAL_realsense_link_9" type="mesh" mesh="MESH_d435_6743a526_9" rgba="0.74901961 0.74901961 0.74901961 1.0" pos="0.0043 -0.0175 0" quat="0.5000000000000001 0.5 0.4999999999999999 0.5"/>
                              <geom class="visual" name="VISUAL_realsense_link_10" type="mesh" mesh="MESH_d435_6743a526_10" rgba="0.74901961 0.74901961 0.74901961 1.0" pos="0.0043 -0.0175 0" quat="0.5000000000000001 0.5 0.4999999999999999 0.5"/>
                              <geom class="visual" name="VISUAL_realsense_link_11" type="mesh" mesh="MESH_d435_6743a526_11" rgba="0.74901961 0.74901961 0.74901961 1.0" pos="0.0043 -0.0175 0" quat="0.5000000000000001 0.5 0.4999999999999999 0.5"/>
                              <geom class="visual" name="VISUAL_realsense_link_12" type="mesh" mesh="MESH_d435_6743a526_12" rgba="0.74901961 0.74901961 0.74901961 1.0" pos="0.0043 -0.0175 0" quat="0.5000000000000001 0.5 0.4999999999999999 0.5"/>
                              <geom class="visual" name="VISUAL_realsense_link_13" type="mesh" mesh="MESH_d435_6743a526_13" rgba="0.74901961 0.74901961 0.74901961 1.0" pos="0.0043 -0.0175 0" quat="0.5000000000000001 0.5 0.4999999999999999 0.5"/>
                              <geom class="visual" name="VISUAL_realsense_link_14" type="mesh" mesh="MESH_d435_6743a526_14" rgba="0.74901961 0.74901961 0.74901961 1.0" pos="0.0043 -0.0175 0" quat="0.5000000000000001 0.5 0.4999999999999999 0.5"/>
                              <geom class="visual" name="VISUAL_realsense_link_15" type="mesh" mesh="MESH_d435_6743a526_15" rgba="0.74901961 0.74901961 0.74901961 1.0" pos="0.0043 -0.0175 0" quat="0.5000000000000001 0.5 0.4999999999999999 0.5"/>
                              <geom class="visual" name="VISUAL_realsense_link_16" type="mesh" mesh="MESH_d435_6743a526_16" rgba="0.74901961 0.74901961 0.74901961 1.0" pos="0.0043 -0.0175 0" quat="0.5000000000000001 0.5 0.4999999999999999 0.5"/>
                              <geom class="visual" name="VISUAL_realsense_link_17" type="mesh" mesh="MESH_d435_6743a526_17" rgba="0.74901961 0.74901961 0.74901961 1.0" pos="0.0043 -0.0175 0" quat="0.5000000000000001 0.5 0.4999999999999999 0.5"/>
                              <camera name="realsense_link_CAMERA" mode="fixed" pos="0 0 0" euler="0 -1.5708 -1.5708" fovy="75" resolution="640 480"/>
                            </body>
                          </body>
                        </body>
                      </body>
                    </body>
                  </body>
                </body>
              </body>
            </body>
          </body>
        </body>
      </body>
      <body name="ur_base" pos="0 0 0" quat="6.123233995736766e-17 0.0 0.0 1.0"/>
    </body>
    <!-- <geom name="floor" type="plane" size="0 0 0.05" material="floor"/> -->
    <light name="default_light" pos="0 0 10" dir="0 0 -1" directional="true"/>
  </worldbody>
  <tendon>
    <fixed name="robotiq_knuckle_tendon">
      <joint joint="robotiq_85_left_knuckle_joint" coef="0.5"/>
      <joint joint="robotiq_85_right_knuckle_joint" coef="-0.5"/>
    </fixed>
  </tendon>
  <contact>
    <exclude body1="ur_base_link_inertia" body2="ur_shoulder_link"/>
    <exclude body1="ur_shoulder_link" body2="ur_upper_arm_link"/>
    <exclude body1="ur_upper_arm_link" body2="ur_forearm_link"/>
    <exclude body1="ur_forearm_link" body2="ur_wrist_1_link"/>
    <exclude body1="ur_wrist_1_link" body2="ur_wrist_2_link"/>
    <exclude body1="ur_wrist_2_link" body2="ur_wrist_3_link"/>
    <exclude body1="robotiq_85_base_link" body2="robotiq_85_left_knuckle_link"/>
    <exclude body1="robotiq_85_base_link" body2="robotiq_85_right_knuckle_link"/>
    <exclude body1="robotiq_85_base_link" body2="robotiq_85_left_inner_knuckle_link"/>
    <exclude body1="robotiq_85_base_link" body2="robotiq_85_right_inner_knuckle_link"/>
    <exclude body1="robotiq_85_left_finger_link" body2="robotiq_85_left_finger_tip_link"/>
    <exclude body1="robotiq_85_right_finger_link" body2="robotiq_85_right_finger_tip_link"/>
    <exclude body1="robotiq_85_left_finger_tip_link" body2="robotiq_85_left_inner_knuckle_link"/>
    <exclude body1="robotiq_85_right_finger_tip_link" body2="robotiq_85_right_inner_knuckle_link"/>
  </contact>
  <actuator>
    <!-- <motor group="0" ctrlrange="-150 150" name="ur_shoulder_pan_joint_ACTUATOR_MOTOR" joint="ur_shoulder_pan_joint"/>
    <motor group="0" ctrlrange="-150 150" name="ur_shoulder_lift_joint_ACTUATOR_MOTOR" joint="ur_shoulder_lift_joint"/>
    <motor group="0" ctrlrange="-150 150" name="ur_elbow_joint_ACTUATOR_MOTOR" joint="ur_elbow_joint"/>
    <motor group="0" ctrlrange="-28  28" name="ur_wrist_1_joint_ACTUATOR_MOTOR" joint="ur_wrist_1_joint"/>
    <motor group="0" ctrlrange="-28  28" name="ur_wrist_2_joint_ACTUATOR_MOTOR" joint="ur_wrist_2_joint"/>
    <motor group="0" ctrlrange="-28  28" name="ur_wrist_3_joint_ACTUATOR_MOTOR" joint="ur_wrist_3_joint"/>
    <motor group="0" ctrlrange="-10  10" name="robotiq_85_left_knuckle_joint_ACTUATOR_MOTOR" joint="robotiq_85_left_knuckle_joint"/> -->

    <position group="1" kp="1e3" dampratio="1.0" ctrlrange="-6.2832 6.2832" forcerange="-150 150" name="ur_shoulder_pan_joint_ACTUATOR_POSITION" joint="ur_shoulder_pan_joint"/>
    <position group="1" kp="1e3" dampratio="1.0" ctrlrange="-6.2832 6.2832" forcerange="-150 150" name="ur_shoulder_lift_joint_ACTUATOR_POSITION" joint="ur_shoulder_lift_joint"/>
    <position group="1" kp="1e3" dampratio="1.0" ctrlrange="-6.2832 6.2832" forcerange="-150 150" name="ur_elbow_joint_ACTUATOR_POSITION" joint="ur_elbow_joint"/>
    <position group="1" kp="1e2" dampratio="1.0" ctrlrange="-6.2832 6.2832" forcerange="-28  28" name="ur_wrist_1_joint_ACTUATOR_POSITION" joint="ur_wrist_1_joint"/>
    <position group="1" kp="1e2" dampratio="1.0" ctrlrange="-6.2832 6.2832" forcerange="-28  28" name="ur_wrist_2_joint_ACTUATOR_POSITION" joint="ur_wrist_2_joint"/>
    <position group="1" kp="1e2" dampratio="1.0" ctrlrange="-6.2832 6.2832" forcerange="-28  28" name="ur_wrist_3_joint_ACTUATOR_POSITION" joint="ur_wrist_3_joint"/>
    <!-- <position group="1" kp="10"  dampratio="1.0" ctrlrange="0.0 0.7929" name="robotiq_85_left_knuckle_joint_ACTUATOR_POSITION" joint="robotiq_85_left_knuckle_joint"/> -->
  </actuator>
  <equality>
    <connect anchor="-0.018 0 0.0065" body1="robotiq_85_left_finger_tip_link" body2="robotiq_85_left_inner_knuckle_link" solimp="0.95 0.99 0.001" solref="0.005 1"/>
    <connect anchor="0.018 0 0.0065" body1="robotiq_85_right_finger_tip_link" body2="robotiq_85_right_inner_knuckle_link" solimp="0.95 0.99 0.001" solref="0.005 1"/>
    <joint joint1="robotiq_85_left_knuckle_joint" joint2="robotiq_85_right_knuckle_joint" polycoef="0.0 -1.0 0.0 0.0 0.0"/>
    <!-- <joint joint1="robotiq_85_left_knuckle_joint" joint2="robotiq_85_left_inner_knuckle_joint" polycoef="0.0 1.0 0.0 0.0 0.0"/>
    <joint joint1="robotiq_85_left_knuckle_joint" joint2="robotiq_85_right_inner_knuckle_joint" polycoef="0.0 -1.0 0.0 0.0 0.0"/>
    <joint joint1="robotiq_85_left_knuckle_joint" joint2="robotiq_85_left_finger_tip_joint" polycoef="0.0 -1.0 0.0 0.0 0.0"/>
    <joint joint1="robotiq_85_left_knuckle_joint" joint2="robotiq_85_right_finger_tip_joint" polycoef="0.0 1.0 0.0 0.0 0.0"/> -->
  </equality>
  <sensor>
    <force name="ur_ft_frame_SENSOR_FORCE" site="ur_ft_frame_SITE"/>
    <torque name="ur_ft_frame_SENSOR_TORQUE" site="ur_ft_frame_SITE"/>
  </sensor>
</mujoco>
